Workbook

Sheet Okuyun
A1: 312 · Ürün süreleri, ayak süreleri, hırdavat ve ahşap parça listesi — v2 (24.10.2026)
A2: Renkler:
A3: • MAVİ yazı = sizin girdiğiniz (veya kütüphanede kayıtlı) değer.
A4: • TURUNCU yazı = Claude tahmini. Kontrol edin, yanlışsa üzerine yazın (yazınca rengi önemli değil, sizin değeriniz geçerli olur).
A5: • YEŞİL yazı = kesim programından / kayıtlı çizimden kesin değer.
A6: • SARI dolgu = düzenlenebilir hücre. GRİ dolgu ve beyaz formüller = dokunmayın.
A8: v2'de ne değişti:
A9: • Yeni sayfa 'Ayak Süreleri': ayak süresi artık ürün satırına değil ayak modeline bağlı (sizin notunuz: Como/Tweety sehpa ayağı 15+30, masa ayağı 15+35). Ürün satırındaki 'Ayak süresi' formülle buradan × ayak adedi gelir.
A10: • 'Ürün Süreleri'ndeki zımpara/montaj = sadece tabla/gövde. Toplam = tabla/gövde + CNC + ayaklar.
A11: • 'Paket içeriği' sütunu eklendi → sipariş defterindeki yükleme listesi (Tabla ☐ Ayak ☐) buradan beslenecek.
A12: • 'Hırdavat' sayfası üç bölüm: (1) ürün gövdesi, (2) AYAK · model · tip (her ayak için — siparişte ayak adedi kadar çarpılır), (3) GENEL kurallar: her paket için ambalaj, LED kuralı.
A13: • Kapak kuralı (sizin notunuz): aşağı açılan kapak = 2 menteşe + 1 amortisör + 1 bas-aç; yana açılan bas-aç kapak = 2 menteşe + 1 bas-aç.
... A18: Bitince dosyayı geri gönderin: kütüphaneye işlenir; sipariş girilince hırdavat ihtiyacı ve iş süreleri otomatik hesaplanır.

Sheet Ürün Süreleri
A1: Ürün | B1: Kategori | C1: Malzeme | D1: Ölçü | E1: Paket (1 ürün) | F1: Paket içeriği (yükleme listesi) | G1: Zımpara — tabla/gövde (dk) | H1: Montaj — tabla/gövde (dk) | I1: CNC kesim — tabla/gövde (dk) | J1: Ayak modeli | K1: Ayak tipi | L1: Ayak adedi | M1: Ayak süresi (dk, formül) | N1: Toplam süre (dk / 1 ürün) | O1: Toplam (saat) | P1: Not
A2: Bonbon Dresuar | B2: Dresuar / konsol | C2: 18 mm MDF | D2: En 150 D45 H90 | E2: 1 | F2: 1 koli: gövde (kapaklar takılı) | G2: 20 | H2: 60 | I2: 22 | J2: Ayak yok | K2: Sehpa | L2: 0 | M2: =L2*SUMIFS('Ayak Süreleri'!$H$2:$H$200,'Ayak Süreleri'!$A$2:$A$200,J2,'Ayak Süreleri'!$B$2:$B$200,K2) -> 0 | N2: =SUM(G2:I2)+M2 -> 102 | O2: =ROUND(N2/60,1) -> 1.7 | P2: CNC: ~1,5 plaka tahmini.
A3: Rotterdam Dresuar Yanlar Tweety Kapaklar Düz | B3: Dresuar / konsol | C3: 18 mm MDF | D3: 160x42 H90 | E3: 1 | F3: 1 koli: gövde (ayaklar gövdeyle tek parça) | G3: 20 | H3: 60 | I3: 25 | J3: Ayak yok | K3: Sehpa | L3: 0 | M3: =L3*SUMIFS('Ayak Süreleri'!$H$2:$H$200,'Ayak Süreleri'!$A$2:$A$200,J3,'Ayak Süreleri'!$B$2:$B$200,K3) -> 0 | N3: =SUM(G3:I3)+M3 -> 105 | O3: =ROUND(N3/60,1) -> 1.8 | P3: 120'lik program 10 dk/plaka; 160×90 ≈ 2 plaka + Tweety yan tarama.
A4: Tweety Çekmece Rotterdam Dresuar | B4: Dresuar / konsol | C4: Hazır plaka (laminat) | D4: En 120 | E4: 1 | F4: 1 koli: gövde + çekmeceler takılı | G4: 10 | H4: 60 | I4: 12 | J4: Ayak yok | K4: Sehpa | L4: 0 | M4: =L4*SUMIFS('Ayak Süreleri'!$H$2:$H$200,'Ayak Süreleri'!$A$2:$A$200,J4,'Ayak Süreleri'!$B$2:$B$200,K4) -> 0 | N4: =SUM(G4:I4)+M4 -> 82 | O4: =ROUND(N4/60,1) -> 1.4 | P4: Rotterdam dresuar 120 programı ~10 dk + çekmece tarama.
A5: Dörtdivan Duvar Paneli (Kertikli, LED'li) | B5: Duvar paneli | C5: Hazır plaka (laminat) | D5: En 380 H249 | E5: 1 | F5: 1 koli: panel parçaları + LED seti | G5: 3 | H5: 25 | I5: 30 | J5: Ayak yok | K5: Sehpa | L5: 0 | M5: =L5*SUMIFS('Ayak Süreleri'!$H$2:$H$200,'Ayak Süreleri'!$A$2:$A$200,J5,'Ayak Süreleri'!$B$2:$B$200,K5) -> 0 | N5: =SUM(G5:I5)+M5 -> 58 | O5: =ROUND(N5/60,1) -> 1 | P5: 380 cm > 280 plaka → 2 program. LED metresi teyit.
A6: Bergamo Masa | B6: Masa | C6: Traverten | D6: 190x100 | E6: 2 | F6: 1: tabla · 2: 4 ayak + şapkalar | G6: 8 | H6: 10 | I6: 5 | J6: Tivoli | K6: Masa | L6: 4 | M6: =L6*SUMIFS('Ayak Süreleri'!$H$2:$H$200,'Ayak Süreleri'!$A$2:$A$200,J6,'Ayak Süreleri'!$B$2:$B$200,K6) -> 236 | N6: =SUM(G6:I6)+M6 -> 259 | O6: =ROUND(N6/60,1) -> 4.3 | P6: Tabla V91 ile 18→4 mm kenar. Tivoli programı tabla+şapka+disk 6,5 dk (kesin).
A7: Danish Oval Masa | B7: Masa | C7: Hazır plaka (laminat) | D7: 200x100 | E7: 2 | F7: 1: tabla · 2: metal ayak | G7: 8 | H7: 10 | I7: 5 | J7: Spider | K7: Masa | L7: 1 | M7: =L7*SUMIFS('Ayak Süreleri'!$H$2:$H$200,'Ayak Süreleri'!$A$2:$A$200,J7,'Ayak Süreleri'!$B$2:$B$200,K7) -> 10 | N7: =SUM(G7:I7)+M7 -> 33 | O7: =ROUND(N7/60,1) -> 0.6
A8: Datça Masa | B8: Masa | C8: 18 mm meşe kaplama | D8: 200x100 | E8: 2 | F8: 1: tabla · 2: metal ayak | G8: 20 | H8: 25 | I8: 12 | J8: Spider | K8: Masa | L8: 1 | M8: =L8*SUMIFS('Ayak Süreleri'!$H$2:$H$200,'Ayak Süreleri'!$A$2:$A$200,J8,'Ayak Süreleri'!$B$2:$B$200,K8) -> 10 | N8: =SUM(G8:I8)+M8 -> 67 | O8: =ROUND(N8/60,1) -> 1.1 | P8: 54 mm kalınlaştırma: tabla + 2 kat 65 mm halka.
A9: Organik Bugatti Masa Camı 4mm | B9: Masa | C9: Cam | D9: 180x100 Organik | E9: 1 | F9: 1: cam (camcıdan) | G9: 0 | H9: 0 | I9: 0 | J9: Ayak yok | K9: Masa | L9: 0 | M9: =L9*SUMIFS('Ayak Süreleri'!$H$2:$H$200,'Ayak Süreleri'!$A$2:$A$200,J9,'Ayak Süreleri'!$B$2:$B$200,K9) -> 0 | N9: =SUM(G9:I9)+M9 -> 0 | O9: =ROUND(N9/60,1) -> 0 | P9: Camcı yapar — atölye süresi yok.
A10: Rotterdam Masa | B10: Masa | C10: Fiscraat | D10: 160x100 | E10: 2 | F10: 1: tabla · 2: metal ayak | G10: 45 | H10: 25 | I10: 15 | J10: Spider | K10: Masa | L10: 1 | M10: =L10*SUMIFS('Ayak Süreleri'!$H$2:$H$200,'Ayak Süreleri'!$A$2:$A$200,J10,'Ayak Süreleri'!$B$2:$B$200,K10) -> 10 | N10: =SUM(G10:I10)+M10 -> 95 | O10: =ROUND(N10/60,1) -> 1.6 | P10: Fiscraat: Artmob kesim + CNC iki geçiş.
A11: Rotterdam Masa Tablası | B11: Masa | C11: Black beton | D11: 170x100 | E11: 1 | F11: 1: tabla | G11: 4 | H11: 25 | I11: 5 | J11: Ayak yok | K11: Masa | L11: 0 | M11: =L11*SUMIFS('Ayak Süreleri'!$H$2:$H$200,'Ayak Süreleri'!$A$2:$A$200,J11,'Ayak Süreleri'!$B$2:$B$200,K11) -> 0 | N11: =SUM(G11:I11)+M11 -> 34 | O11: =ROUND(N11/60,1) -> 0.6
A12: Round Bugatti Masa | B12: Masa | C12: Traverten | D12: Ø105 | E12: 2 | F12: 1: tabla · 2: XL ayak | G12: 8 | H12: 25 | I12: 9 | J12: XL Como | K12: Masa | L12: 1 | M12: =L12*SUMIFS('Ayak Süreleri'!$H$2:$H$200,'Ayak Süreleri'!$A$2:$A$200,J12,'Ayak Süreleri'!$B$2:$B$200,K12) -> 73 | N12: =SUM(G12:I12)+M12 -> 115 | O12: =ROUND(N12/60,1) -> 1.9 | P12: Bugatti = 54 mm kalınlaştırma kabul edildi.
A13: Slim Bugatti Masa | B13: Masa | C13: Hazır plaka (laminat) | D13: 160x100 | E13: 3 | F13: 1: tabla · 2–3: ayaklar | G13: 8 | H13: 10 | I13: 5 | J13: Tweety | K13: Masa | L13: 2 | M13: =L13*SUMIFS('Ayak Süreleri'!$H$2:$H$200,'Ayak Süreleri'!$A$2:$A$200,J13,'Ayak Süreleri'!$B$2:$B$200,K13) -> 112 | N13: =SUM(G13:I13)+M13 -> 135 | O13: =ROUND(N13/60,1) -> 2.3
A14: Slim Masa | B14: Masa | C14: Traverten | D14: Ø100 | E14: 2 | F14: 1: tabla · 2: ayak | G14: 8 | H14: 10 | I14: 4 | J14: Tweety | K14: Masa | L14: 1 | M14: =L14*SUMIFS('Ayak Süreleri'!$H$2:$H$200,'Ayak Süreleri'!$A$2:$A$200,J14,'Ayak Süreleri'!$B$2:$B$200,K14) -> 56 | N14: =SUM(G14:I14)+M14 -> 78 | O14: =ROUND(N14/60,1) -> 1.3
A15: Babuşka Orta Sehpa | B15: Sehpa | C15: 18 mm meşe kaplama | D15: Ø100 + Ø80 | E15: 1 | F15: 1 koli: 2 tabla + metal ayak | G15: 20 | H15: 30 | I15: 6 | J15: Babuşka | K15: Sehpa | L15: 1 | M15: =L15*SUMIFS('Ayak Süreleri'!$H$2:$H$200,'Ayak Süreleri'!$A$2:$A$200,J15,'Ayak Süreleri'!$B$2:$B$200,K15) -> 10 | N15: =SUM(G15:I15)+M15 -> 66 | O15: =ROUND(N15/60,1) -> 1.1
A16: Bergamo Orta Sehpa | B16: Sehpa | C16: Traverten | D16: 110x75 | E16: 2 | F16: 1: tabla · 2: ayak | G16: 4 | H16: 10 | I16: 4 | J16: Apollo | K16: Sehpa | L16: 1 | M16: =L16*SUMIFS('Ayak Süreleri'!$H$2:$H$200,'Ayak Süreleri'!$A$2:$A$200,J16,'Ayak Süreleri'!$B$2:$B$200,K16) -> 49 | N16: =SUM(G16:I16)+M16 -> 67 | O16: =ROUND(N16/60,1) -> 1.1
A17: Bonbon Tweety TV Sehpası | B17: Sehpa | C17: Hazır plaka (laminat) | D17: En 120 | E17: 1 | F17: 1 koli: gövde | G17: 20 | H17: 60 | I17: 15 | J17: Ayak yok | K17: Sehpa | L17: 0 | M17: =L17*SUMIFS('Ayak Süreleri'!$H$2:$H$200,'Ayak Süreleri'!$A$2:$A$200,J17,'Ayak Süreleri'!$B$2:$B$200,K17) -> 0 | N17: =SUM(G17:I17)+M17 -> 95 | O17: =ROUND(N17/60,1) -> 1.6
A18: Danish Oval Orta Sehpa | B18: Sehpa | C18: Hazır plaka (laminat) | D18: 140x70 | E18: 2 | F18: 1: tabla · 2: metal ayak | G18: 4 | H18: 5 | I18: 4 | J18: Spider | K18: Sehpa | L18: 1 | M18: =L18*SUMIFS('Ayak Süreleri'!$H$2:$H$200,'Ayak Süreleri'!$A$2:$A$200,J18,'Ayak Süreleri'!$B$2:$B$200,K18) -> 5 | N18: =SUM(G18:I18)+M18 -> 18 | O18: =ROUND(N18/60,1) -> 0.3
A19: Lazy Top Sehpa | B19: Sehpa | C19: Traverten | D19: Ø90 H40 | E19: 2 | F19: 1: tabla · 2: ayak | G19: 4 | H19: 15 | I19: 4 | J19: Tweens Tweety | K19: Sehpa | L19: 1 | M19: =L19*SUMIFS('Ayak Süreleri'!$H$2:$H$200,'Ayak Süreleri'!$A$2:$A$200,J19,'Ayak Süreleri'!$B$2:$B$200,K19) -> 71 | N19: =SUM(G19:I19)+M19 -> 94 | O19: =ROUND(N19/60,1) -> 1.6
A20: Ollie Orta Sehpa | B20: Sehpa | C20: Traverten | D20: Ø90 | E20: 1 | F20: 1 koli | G20: 4 | H20: 35 | I20: 4 | J20: Ayak yok | K20: Sehpa | L20: 0 | M20: =L20*SUMIFS('Ayak Süreleri'!$H$2:$H$200,'Ayak Süreleri'!$A$2:$A$200,J20,'Ayak Süreleri'!$B$2:$B$200,K20) -> 0 | N20: =SUM(G20:I20)+M20 -> 43 | O20: =ROUND(N20/60,1) -> 0.7
A21: Rotterdam Orta Sehpa | B21: Sehpa | C21: Traverten | D21: 110x60 H45 | E21: 3 | F21: 1: tabla · 2–3: 2 ayak | G21: 4 | H21: 15 | I21: 8 | J21: Como | K21: Sehpa | L21: 2 | M21: =L21*SUMIFS('Ayak Süreleri'!$H$2:$H$200,'Ayak Süreleri'!$A$2:$A$200,J21,'Ayak Süreleri'!$B$2:$B$200,K21) -> 98 | N21: =SUM(G21:I21)+M21 -> 125 | O21: =ROUND(N21/60,1) -> 2.1 | P21: Rotterdam = 54 mm haşon kenar.
A22: Rotterdam Orta Sehpa Tablası | B22: Sehpa | C22: Black beton | D22: 140x80 | E22: 1 | F22: 1: tabla | G22: 4 | H22: 15 | I22: 4 | J22: Ayak yok | K22: Sehpa | L22: 0 | M22: =L22*SUMIFS('Ayak Süreleri'!$H$2:$H$200,'Ayak Süreleri'!$A$2:$A$200,J22,'Ayak Süreleri'!$B$2:$B$200,K22) -> 0 | N22: =SUM(G22:I22)+M22 -> 23 | O22: =ROUND(N22/60,1) -> 0.4
A23: Slim Bugatti Sehpa | B23: Sehpa | C23: Hazır plaka (laminat) | D23: 120x70 | E23: 3 | F23: 1: tabla · 2–3: ayaklar | G23: 4 | H23: 5 | I23: 4 | J23: Tweety | K23: Sehpa | L23: 2 | M23: =L23*SUMIFS('Ayak Süreleri'!$H$2:$H$200,'Ayak Süreleri'!$A$2:$A$200,J23,'Ayak Süreleri'!$B$2:$B$200,K23) -> 98 | N23: =SUM(G23:I23)+M23 -> 111 | O23: =ROUND(N23/60,1) -> 1.9
A24: Slim Orta Sehpa (2'li) | B24: Sehpa | C24: Traverten | D24: Ø70 H40 + Ø55 H45 | E24: 3 | F24: 1: Ø70 tabla · 2: Ø55 tabla · 3: 2 ayak | G24: 8 | H24: 10 | I24: 6 | J24: Tweens Tweety | K24: Sehpa | L24: 2 | M24: =L24*SUMIFS('Ayak Süreleri'!$H$2:$H$200,'Ayak Süreleri'!$A$2:$A$200,J24,'Ayak Süreleri'!$B$2:$B$200,K24) -> 142 | N24: =SUM(G24:I24)+M24 -> 166 | O24: =ROUND(N24/60,1) -> 2.8 | P24: Paket dağılımı tahmini.
A25: Slim Orta Sehpa Sadece Tabla | B25: Sehpa | C25: 18 mm MDF | D25: Ø90 + Ø70 | E25: 1 | F25: 1: Ø90 + Ø70 tabla | G25: 8 | H25: 5 | I25: 5 | J25: Ayak yok | K25: Sehpa | L25: 0 | M25: =L25*SUMIFS('Ayak Süreleri'!$H$2:$H$200,'Ayak Süreleri'!$A$2:$A$200,J25,'Ayak Süreleri'!$B$2:$B$200,K25) -> 0 | N25: =SUM(G25:I25)+M25 -> 18 | O25: =ROUND(N25/60,1) -> 0.3
A26: Torino Orta Sehpa Set | B26: Sehpa | C26: 18 mm meşe kaplama | D26: Standart | E26: 4 | F26: 1–3: 3 tabla · 4: 3 ayak | G26: 20 | H26: 15 | I26: 8 | J26: Como | K26: Sehpa | L26: 3 | M26: =L26*SUMIFS('Ayak Süreleri'!$H$2:$H$200,'Ayak Süreleri'!$A$2:$A$200,J26,'Ayak Süreleri'!$B$2:$B$200,K26) -> 147 | N26: =SUM(G26:I26)+M26 -> 190 | O26: =ROUND(N26/60,1) -> 3.2 | P26: Set: Como Ø60 H43 ×2 + Ø39 H38 ×1 (312-0008).
A27: Torino Yan Sehpa Tweety Ayak | B27: Sehpa | C27: Traverten | D27: H45 | E27: 2 | F27: 1: tabla · 2: ayak | G27: 3 | H27: 5 | I27: 3 | J27: Tweety | K27: Sehpa | L27: 1 | M27: =L27*SUMIFS('Ayak Süreleri'!$H$2:$H$200,'Ayak Süreleri'!$A$2:$A$200,J27,'Ayak Süreleri'!$B$2:$B$200,K27) -> 49 | N27: =SUM(G27:I27)+M27 -> 60 | O27: =ROUND(N27/60,1) -> 1 | P27: Aşağıdaki "H45" satırıyla aynı ürün — birleştirelim mi? (Sorular)
A28: Torino Yan Sehpa Tweety Ayak H45 | B28: Sehpa | C28: Traverten | D28: H45 | E28: 2 | F28: 1: tabla · 2: ayak | G28: 3 | H28: 5 | I28: 3 | J28: Tweety | K28: Sehpa | L28: 1 | M28: =L28*SUMIFS('Ayak Süreleri'!$H$2:$H$200,'Ayak Süreleri'!$A$2:$A$200,J28,'Ayak Süreleri'!$B$2:$B$200,K28) -> 49 | N28: =SUM(G28:I28)+M28 -> 60 | O28: =ROUND(N28/60,1) -> 1
A29: Winston Orta Sehpa | B29: Sehpa | C29: 18 mm meşe kaplama | D29: 130x90 H40 | E29: 2 | F29: 1: tabla · 2: ayak | G29: 20 | H29: 40 | I29: 5 | J29: Como | K29: Sehpa | L29: 1 | M29: =L29*SUMIFS('Ayak Süreleri'!$H$2:$H$200,'Ayak Süreleri'!$A$2:$A$200,J29,'Ayak Süreleri'!$B$2:$B$200,K29) -> 49 | N29: =SUM(G29:I29)+M29 -> 114 | O29: =ROUND(N29/60,1) -> 1.9
A30: Sineklik Cam 1 | B30: Sineklik | C30: Sineklik | D30: En 51,7 H132 | E30: 1 | F30: 1 | G30: 0 | H30: 0 | I30: 0 | J30: Ayak yok | K30: Sehpa | L30: 0 | M30: =L30*SUMIFS('Ayak Süreleri'!$H$2:$H$200,'Ayak Süreleri'!$A$2:$A$200,J30,'Ayak Süreleri'!$B$2:$B$200,K30) -> 0 | N30: =SUM(G30:I30)+M30 -> 0 | O30: =ROUND(N30/60,1) -> 0 | P30: Sineklik Emir yapar.
A31: Sineklik Cam 2 | B31: Sineklik | C31: Sineklik | D31: En 64,5 H170,5 | E31: 1 | F31: 1 | G31: 0 | H31: 0 | I31: 0 | J31: Ayak yok | K31: Sehpa | L31: 0 | M31: =L31*SUMIFS('Ayak Süreleri'!$H$2:$H$200,'Ayak Süreleri'!$A$2:$A$200,J31,'Ayak Süreleri'!$B$2:$B$200,K31) -> 0 | N31: =SUM(G31:I31)+M31 -> 0 | O31: =ROUND(N31/60,1) -> 0
A32: Sineklik Cam 3 | B32: Sineklik | C32: Sineklik | D32: En 65 H170,5 | E32: 1 | F32: 1 | G32: 0 | H32: 0 | I32: 0 | J32: Ayak yok | K32: Sehpa | L32: 0 | M32: =L32*SUMIFS('Ayak Süreleri'!$H$2:$H$200,'Ayak Süreleri'!$A$2:$A$200,J32,'Ayak Süreleri'!$B$2:$B$200,K32) -> 0 | N32: =SUM(G32:I32)+M32 -> 0 | O32: =ROUND(N32/60,1) -> 0
A33: Sineklik Kapı Ev Çıkış (Soldan Sağa Açılacak) | B33: Sineklik | C33: Sineklik | D33: En 99 H228,3 | E33: 1 | F33: 1 | G33: 0 | H33: 0 | I33: 0 | J33: Ayak yok | K33: Sehpa | L33: 0 | M33: =L33*SUMIFS('Ayak Süreleri'!$H$2:$H$200,'Ayak Süreleri'!$A$2:$A$200,J33,'Ayak Süreleri'!$B$2:$B$200,K33) -> 0 | N33: =SUM(G33:I33)+M33 -> 0 | O33: =ROUND(N33/60,1) -> 0
A34: Sineklik İkinci Mutfak (Soldan Sağa Açılacak) | B34: Sineklik | C34: Sineklik | D34: En 107 H228 | E34: 1 | F34: 1 | G34: 0 | H34: 0 | I34: 0 | J34: Ayak yok | K34: Sehpa | L34: 0 | M34: =L34*SUMIFS('Ayak Süreleri'!$H$2:$H$200,'Ayak Süreleri'!$A$2:$A$200,J34,'Ayak Süreleri'!$B$2:$B$200,K34) -> 0 | N34: =SUM(G34:I34)+M34 -> 0 | O34: =ROUND(N34/60,1) -> 0
A35: Angel TV Ünitesi 4 Kapak, Lazer TV Metal Ayak | B35: TV ünitesi | C35: Hazır plaka (laminat) | D35: En 250 | E35: 1 | F35: 1 koli: gövde · ayaklar kutuda | G35: 5 | H35: 40 | I35: 25 | J35: Lazer metal | K35: Sehpa | L35: 4 | M35: =L35*SUMIFS('Ayak Süreleri'!$H$2:$H$200,'Ayak Süreleri'!$A$2:$A$200,J35,'Ayak Süreleri'!$B$2:$B$200,K35) -> 20 | N35: =SUM(G35:I35)+M35 -> 90 | O35: =ROUND(N35/60,1) -> 1.5 | P35: Taramalı yarım elips yanlar.
A36: Bonbon TV Ünitesi | B36: TV ünitesi | C36: 18 mm MDF | D36: En 300 | E36: 1 | F36: 1 koli: gövde | G36: 20 | H36: 60 | I36: 35 | J36: Ayak yok | K36: Sehpa | L36: 0 | M36: =L36*SUMIFS('Ayak Süreleri'!$H$2:$H$200,'Ayak Süreleri'!$A$2:$A$200,J36,'Ayak Süreleri'!$B$2:$B$200,K36) -> 0 | N36: =SUM(G36:I36)+M36 -> 115 | O36: =ROUND(N36/60,1) -> 1.9 | P36: 300 cm > 280 → iki programlı yöntem (plaka çevrilir).
A37: Dolap, Lazer TV Metal Ayak | B37: TV ünitesi | C37: Hazır plaka (laminat) | D37: En 105 D45 H200 | E37: 1 | F37: 1 koli: gövde + kapaklar · ayaklar kutuda | G37: 20 | H37: 60 | I37: 20 | J37: Lazer metal | K37: Sehpa | L37: 4 | M37: =L37*SUMIFS('Ayak Süreleri'!$H$2:$H$200,'Ayak Süreleri'!$A$2:$A$200,J37,'Ayak Süreleri'!$B$2:$B$200,K37) -> 20 | N37: =SUM(G37:I37)+M37 -> 120 | O37: =ROUND(N37/60,1) -> 2
A38: Star TV Ünitesi Şömine 200cm | B38: TV ünitesi | C38: Fiscraat | D38: En 128 | E38: 1 | F38: 1 koli | G38: 30 | H38: 45 | I38: 15 | J38: Ayak yok | K38: Sehpa | L38: 0 | M38: =L38*SUMIFS('Ayak Süreleri'!$H$2:$H$200,'Ayak Süreleri'!$A$2:$A$200,J38,'Ayak Süreleri'!$B$2:$B$200,K38) -> 0 | N38: =SUM(G38:I38)+M38 -> 90 | O38: =ROUND(N38/60,1) -> 1.5 | P38: Ölçü En128 yazıyor ama adı 200cm — aşağıdakiyle karışmış olabilir (Sorular).
A39: Star TV Ünitesi Şömineli | B39: TV ünitesi | C39: Fiscraat | D39: En 200 | E39: 1 | F39: 1 koli | G39: 45 | H39: 60 | I39: 30 | J39: Ayak yok | K39: Sehpa | L39: 0 | M39: =L39*SUMIFS('Ayak Süreleri'!$H$2:$H$200,'Ayak Süreleri'!$A$2:$A$200,J39,'Ayak Süreleri'!$B$2:$B$200,K39) -> 0 | N39: =SUM(G39:I39)+M39 -> 135 | O39: =ROUND(N39/60,1) -> 2.3 | P39: Dimplex 128 cm şömineye göre; Fiscraat iki geçiş.
A41: Sizin notlarınız (Ayak Süreleri sayfasına işlendi):
...

Sheet Ayak Süreleri
A1: Ayak modeli | B1: Tip | C1: Ölçü aralığı | D1: Malzeme | E1: Zımpara (dk / 1 ayak) | F1: Montaj (dk / 1 ayak) | G1: CNC kesim (dk / 1 ayak) | H1: Toplam (dk / 1 ayak) | I1: Kaynak | J1: Not
A2: Como | B2: Sehpa | C2: Ø29–64, H38/43/48 | D2: 18 mm MDF / meşe | E2: 15 | F2: 30 | G2: 4 | H2: =SUM(E2:G2) -> 49 | I2: Murat / CNC: Claude tahmini | J2: Murat: tüm çaplarda aynı süre. CNC: tarama panel + 2 kapak (fire plakadan).
A3: Como | B3: Masa | C3: Ø39–60, H73 | D3: 18 mm MDF / meşe | E3: 15 | F3: 35 | G3: 7 | H3: =SUM(E3:G3) -> 57 | I3: Murat / CNC: Claude tahmini | J3: Panel 1233 + 2×Ø390 kapak + 4 çeyrek yay şapka.
A4: XL Como | B4: Masa | C4: H73 | D4: 18 mm MDF | E4: 20 | F4: 45 | G4: 8 | H4: =SUM(E4:G4) -> 73 | I4: Claude tahmini / CNC: Claude tahmini | J4: Como masadan büyük; süreler tahmin.
A5: Tweety | B5: Sehpa | C5: Ø29–64, H38/43/48 | D5: 18 mm MDF / meşe | E5: 15 | F5: 30 | G5: 4 | H5: =SUM(E5:G5) -> 49 | I5: Murat / CNC: Claude tahmini | J5: Murat: Como ile aynı.
A6: Tweety | B6: Masa | C6: Ø39–60, H73 | D6: 18 mm MDF / meşe | E6: 15 | F6: 35 | G6: 6 | H6: =SUM(E6:G6) -> 56 | I6: Murat / CNC: Claude tahmini
A7: Tweens Tweety | B7: Sehpa | C7: 2 kolon birleşik | D7: 18 mm MDF | E7: 20 | F7: 45 | G7: 6 | H7: =SUM(E7:G7) -> 71 | I7: Claude tahmini / CNC: Claude tahmini | J7: İki kolonlu ayak; tek Tweety × 1,4 tahmini.
A8: Tivoli | B8: Masa | C8: Ø10 (≈Ø106 dış), H73 | D8: 18 mm MDF + 8 mm tarama | E8: 15 | F8: 40 | G8: 4 | H8: =SUM(E8:G8) -> 59 | I8: Claude tahmini / CNC: Program / hafıza (kesin) | J8: Cannelé: 3 disk Ø90 + elde çıtalar + 8 mm Tweety tarama sarma + Ø150 şapka. Çıta kesimi elde → montaj uzun.
A9: Torino | B9: Sehpa | C9: H38/43/48 | D9: 18 mm meşe | E9: 15 | F9: 30 | G9: 4 | H9: =SUM(E9:G9) -> 49 | I9: Claude tahmini / CNC: Claude tahmini | J9: Como ile aynı kabul edildi.
A10: Apollo | B10: Sehpa | C10: Standart / ölçülü | D10: 18 mm MDF | E10: 15 | F10: 30 | G10: 4 | H10: =SUM(E10:G10) -> 49 | I10: Claude tahmini / CNC: Claude tahmini
A11: Apollo | B11: Masa | C11: Standart / ölçülü | D11: 18 mm MDF | E11: 15 | F11: 35 | G11: 7 | H11: =SUM(E11:G11) -> 57 | I11: Claude tahmini / CNC: Claude tahmini
A12: Bubble konik | B12: Masa | C12: Ø548/305 H714 | D12: 18 mm MDF | E12: 20 | F12: 40 | G12: 8 | H12: =SUM(E12:G12) -> 68 | I12: Claude tahmini / CNC: Claude tahmini | J12: Gönye burun; hedef işçiliksiz oturma. Program denenince güncellenecek.
A13: Bubble konik | B13: Sehpa | C13: Ø498/298 H382, Ø348/198 H432 | D13: 18 mm MDF | E13: 15 | F13: 35 | G13: 6 | H13: =SUM(E13:G13) -> 56 | I13: Claude tahmini / CNC: Claude tahmini
A14: Spider | B14: Masa | C14: H73 | D14: Metal (Özbulut) | E14: 0 | F14: 10 | G14: 0 | H14: =SUM(E14:G14) -> 10 | I14: Claude tahmini / CNC: Tedarikçi | J14: Metal hazır gelir; montaj = tablaya takma + kontrol.
A15: Spider | B15: Sehpa | C15: H38–48 | D15: Metal (Özbulut) | E15: 0 | F15: 5 | G15: 0 | H15: =SUM(E15:G15) -> 5 | I15: Claude tahmini / CNC: Tedarikçi
A16: Milano Spider | B16: Masa | C16: H73 | D16: Metal (Özbulut) | E16: 0 | F16: 10 | G16: 0 | H16: =SUM(E16:G16) -> 10 | I16: Claude tahmini / CNC: Tedarikçi
A17: Milano Spider | B17: Sehpa | C17: H38–48 | D17: Metal (Özbulut) | E17: 0 | F17: 5 | G17: 0 | H17: =SUM(E17:G17) -> 5 | I17: Claude tahmini / CNC: Tedarikçi
A18: Designer | B18: Sehpa | C18: Ø90 H40 / Ø68 H36 | D18: Metal (Özbulut) | E18: 0 | F18: 5 | G18: 0 | H18: =SUM(E18:G18) -> 5 | I18: Claude tahmini / CNC: Tedarikçi
A19: Babuşka | B19: Sehpa | C19: — | D19: Metal (Özbulut) | E19: 0 | F19: 10 | G19: 0 | H19: =SUM(E19:G19) -> 10 | I19: Claude tahmini / CNC: Tedarikçi | J19: Ø/H ölçüsü henüz yok.
A20: Lazer metal | B20: Sehpa | C20: H15 | D20: Metal (Özbulut) | E20: 0 | F20: 5 | G20: 0 | H20: =SUM(E20:G20) -> 5 | I20: Claude tahmini / CNC: Tedarikçi | J20: TV ünitesi/dolap ayağı. Tip "Sehpa" = masa dışı tüm ürünler.
A21: Ayak yok | B21: Sehpa | E21: 0 | F21: 0 | G21: 0 | H21: =SUM(E21:G21) -> 0 | I21: Claude tahmini / CNC: Tedarikçi | J21: Formül için boş satır.
A22: Ayak yok | B22: Masa | E22: 0 | F22: 0 | G22: 0 | H22: =SUM(E22:G22) -> 0 | I22: Claude tahmini / CNC: Tedarikçi

Sheet Hırdavat
A1: Ürün / ayak / kural | B1: Hırdavat | C1: Miktar (1 ürün / 1 ayak / 1 paket) | D1: Birim | E1: Hesap kuralı | F1: Kaynak | G1: Not
A2: 1) ÜRÜN GÖVDESİ — 1 ürün için (ayak bağlantısı burada değil, 2. bölümde)
A3: Bonbon TV Ünitesi | B3: Menteşe | C3: 8 | D3: adet | E3: Aşağı açılan kapak başı 2 | F3: Murat | G3: Murat: 4 kapaklı tasarım; kapak sayısına göre değişir
A4: Bonbon TV Ünitesi | B4: Amortisör | C4: 4 | D4: adet | E4: Aşağı açılan kapak başı 1 | F4: Murat
A5: Bonbon TV Ünitesi | B5: Bas-aç (push) | C5: 4 | D5: adet | E5: Kapak başı 1 | F5: Murat
A6: Bonbon TV Ünitesi | B6: Keçe (ayak altı) | C6: 4 | D6: adet | F6: Claude tahmini | G6: Zemine oturuyorsa; duvara asılıysa askı kancası
A7: Bonbon Dresuar | B7: Menteşe | C7: 8 | D7: adet | E7: Yana açılan kapak başı 2 | F7: Claude tahmini | G7: 150 cm → 4 kapak varsayıldı
A8: Bonbon Dresuar | B8: Bas-aç (push) | C8: 4 | D8: adet | E8: Kapak başı 1 | F8: Claude tahmini
A9: Bonbon Dresuar | B9: Keçe (ayak altı) | C9: 4 | D9: adet | F9: Claude tahmini
A10: Rotterdam Dresuar Yanlar Tweety Kapaklar Düz | B10: Menteşe | C10: 8 | D10: adet | E10: Yana açılan kapak başı 2 | F10: Kütüphane | G10: Kütüphanede kayıtlı
A11: Rotterdam Dresuar Yanlar Tweety Kapaklar Düz | B11: Bas-aç (push) | C11: 4 | D11: adet | E11: Kapak başı 1 | F11: Kütüphane | G11: Kütüphanede kayıtlı
A12: Rotterdam Dresuar Yanlar Tweety Kapaklar Düz | B12: Keçe (ayak altı) | C12: 4 | D12: adet | F12: Claude tahmini
A13: Tweety Çekmece Rotterdam Dresuar | B13: Çekmece rayı | C13: 2 | D13: çift | E13: Çekmece başı 1 çift (Samet 350) | F13: Kütüphane | G13: Kütüphanede "2 adet" yazıyordu → 2 çekmece = 2 çift
A14: Tweety Çekmece Rotterdam Dresuar | B14: Vida 4x16 | C14: 24 | D14: adet | E14: Ray çifti başı 12 | F14: Claude tahmini
A15: Tweety Çekmece Rotterdam Dresuar | B15: Keçe (ayak altı) | C15: 4 | D15: adet | F15: Claude tahmini
A16: Dörtdivan Duvar Paneli (Kertikli, LED'li) | B16: LED şerit | C16: 7.6 | D16: m | E16: Panel eni × 2 (tahmin) | F16: Claude tahmini | G16: LED metresi teyit — kertik başına mı, üst/alt mı?
A17: Dörtdivan Duvar Paneli (Kertikli, LED'li) | B17: LED trafo | C17: 1 | D17: adet | E17: 8 m'ye kadar 1 (60 W) | F17: Claude tahmini
A18: Dörtdivan Duvar Paneli (Kertikli, LED'li) | B18: LED bağlantı seti (kablo + konnektör) | C18: 1 | D18: takım | F18: Claude tahmini
A19: Dörtdivan Duvar Paneli (Kertikli, LED'li) | B19: Duvar dübeli + vida 6x60 | C19: 12 | D19: adet | F19: Claude tahmini
A20: Organik Bugatti Masa Camı 4mm | B20: Cam altı şeffaf tampon | C20: 6 | D20: adet | F20: Claude tahmini | G20: Cam tabla üstünde kaymasın
A21: Datça Masa | B21: Yapıştırıcı / tutkal | C21: 0.3 | D21: kg | E21: 54 mm kalınlaştırma | F21: Claude tahmini
A22: Round Bugatti Masa | B22: Yapıştırıcı / tutkal | C22: 0.2 | D22: kg | E22: 54 mm kalınlaştırma | F22: Claude tahmini
A23: Rotterdam Orta Sehpa | B23: Yapıştırıcı / tutkal | C23: 0.2 | D23: kg | E23: Haşon gönye | F23: Claude tahmini
A24: Babuşka Orta Sehpa | B24: Vida 4x16 | C24: 8 | D24: adet | E24: Tabla başı 4 (metal çerçeveye) | F24: Claude tahmini
A25: Bonbon Tweety TV Sehpası | B25: Bas-aç (push) | C25: 1 | D25: adet | F25: Kütüphane | G25: Kütüphanede kayıtlı
A26: Bonbon Tweety TV Sehpası | B26: Menteşe | C26: 2 | D26: adet | F26: Kütüphane | G26: Kütüphanede kayıtlı
A27: Bonbon Tweety TV Sehpası | B27: Kalkar kapak mekanizması | C27: 1 | D27: adet | F27: Kütüphane | G27: Kütüphanede kayıtlı
A28: Angel TV Ünitesi 4 Kapak, Lazer TV Metal Ayak | B28: Menteşe | C28: 6 | D28: adet | F28: Kütüphane | G28: Kütüphanede kayıtlı (4 kapak için 8 olmalı mı? Sorular)
A29: Angel TV Ünitesi 4 Kapak, Lazer TV Metal Ayak | B29: Amortisör | C29: 3 | D29: adet | F29: Kütüphane | G29: Kütüphanede kayıtlı
A30: Dolap, Lazer TV Metal Ayak | B30: Menteşe | C30: 6 | D30: adet | E30: H200 kapak başı 3 (2 kapak) | F30: Claude tahmini
A31: Dolap, Lazer TV Metal Ayak | B31: Raf pimi | C31: 16 | D31: adet | E31: Raf başı 4 | F31: Claude tahmini | G31: 4 raf varsayıldı
A32: Dolap, Lazer TV Metal Ayak | B32: Kulp | C32: 2 | D32: adet | F32: Claude tahmini | G32: Bas-aç ise kulp yerine 2 bas-aç
A33: Star TV Ünitesi Şömineli | B33: Menteşe | C33: 4 | D33: adet | F33: Kütüphane | G33: Kütüphanede kayıtlı
A34: Star TV Ünitesi Şömineli | B34: Bas-aç (push) | C34: 2 | D34: adet | F34: Kütüphane | G34: Kütüphanede kayıtlı
A35: Star TV Ünitesi Şömineli | B35: Kablo geçiş rozeti | C35: 2 | D35: adet | F35: Claude tahmini
A36: Sineklik Cam 1 | B36: — (tedarikçi dahil) | C36: 0 | D36: adet | F36: Tedarikçi | G36: Sineklik Emir komple getirir
A37: Sineklik Cam 2 | B37: — (tedarikçi dahil) | C37: 0 | D37: adet | F37: Tedarikçi | G37: Sineklik Emir komple getirir
A38: Sineklik Cam 3 | B38: — (tedarikçi dahil) | C38: 0 | D38: adet | F38: Tedarikçi | G38: Sineklik Emir komple getirir
A39: Sineklik Kapı Ev Çıkış (Soldan Sağa Açılacak) | B39: — (tedarikçi dahil) | C39: 0 | D39: adet | F39: Tedarikçi | G39: Sineklik Emir komple getirir
A40: Sineklik İkinci Mutfak (Soldan Sağa Açılacak) | B40: — (tedarikçi dahil) | C40: 0 | D40: adet | F40: Tedarikçi | G40: Sineklik Emir komple getirir
...

Sheet Ahşap Parçalar
A1: Ürün | B1: Parça adı | C1: En / Ø (mm) | D1: Boy (mm) | E1: Kalınlık (mm) | F1: Adet (1 ürün için) | G1: Malzeme | H1: Kaynak | I1: Not
A2: ÖRNEK · Datça Masa | B2: Tabla | C2: 2000 | D2: 1000 | E2: 54 | F2: 1 | G2: 18 mm meşe kaplama | H2: Murat | I2: Örnek — Murat 54 mm düzeltti (18 + 2 kat halka)
A3: Bonbon Dresuar | B3: tek parça | F3: 1 | H3: Murat | I3: Murat: tek parça (gövde montajlı gider). Parça listesi kesim programı çıkınca eklenir.
A4: Rotterdam Dresuar Yanlar Tweety Kapaklar Düz | B4: tek parça | F4: 1 | H4: Murat | I4: Murat: tek parça (gövde montajlı gider). Parça listesi kesim programı çıkınca eklenir.
A5: Tweety Çekmece Rotterdam Dresuar | B5: tek parça | F5: 1 | H5: Murat | I5: Murat: tek parça (gövde montajlı gider). Parça listesi kesim programı çıkınca eklenir.
A6: Dörtdivan Duvar Paneli (Kertikli, LED'li) | B6: tek parça | F6: 1 | H6: Murat | I6: Murat: tek parça (gövde montajlı gider). Parça listesi kesim programı çıkınca eklenir.
A7: Bergamo Masa | B7: Tabla (oval) | C7: 1900 | D7: 1000 | E7: 18 | F7: 1 | G7: Traverten (Starwood) | H7: Program / hafıza (kesin) | I7: Murat: tabla. Alttan V91 ile kenar 4 mm'ye inceltilir (Tivoli programı)
A8: Rotterdam Dresuar 120 (program REF) | B8: Bacak dış | C8: 800 | D8: 400 | E8: 18 | F8: 2 | G8: 18 mm MDF | H8: Program / hafıza (kesin) | I8: 54 mm kutu, tüm kenarlar gönye (V91). ROTTERDAM_DRESUAR_120x40x80.anc
A9: Rotterdam Dresuar 120 (program REF) | B9: Bacak iç | C9: 746 | D9: 400 | E9: 18 | F9: 2 | G9: 18 mm MDF | H9: Program / hafıza (kesin)
A10: Rotterdam Dresuar 120 (program REF) | B10: Bacak şerit A/B (45° uçlu, ayna) | C10: 800 | D10: 54 | E10: 18 | F10: 4 | G10: 18 mm MDF | H10: Program / hafıza (kesin)
A11: Rotterdam Dresuar 120 (program REF) | B11: Üst | C11: 1200 | D11: 400 | E11: 18 | F11: 1 | G11: 18 mm MDF | H11: Program / hafıza (kesin)
A12: Rotterdam Dresuar 120 (program REF) | B12: Tavan | C12: 1092 | D12: 400 | E12: 18 | F12: 1 | G12: 18 mm MDF | H12: Program / hafıza (kesin)
A13: Rotterdam Dresuar 120 (program REF) | B13: Üst şerit | C13: 1200 | D13: 54 | E13: 18 | F13: 1 | G13: 18 mm MDF | H13: Program / hafıza (kesin)
A14: Rotterdam Dresuar 120 (program REF) | B14: Tavan şerit | C14: 1092 | D14: 54 | E14: 18 | F14: 1 | G14: 18 mm MDF | H14: Program / hafıza (kesin)
A15: Rotterdam Dresuar 120 (program REF) | B15: Raf | C15: 1092 | D15: 374 | E15: 18 | F15: 1 | G15: 18 mm MDF | H15: Program / hafıza (kesin) | I15: 26 mm geride
A16: Rotterdam Dresuar 120 (program REF) | B16: Arkalık | C16: 1092 | D16: 150 | E16: 18 | F16: 1 | G16: 18 mm MDF | H16: Program / hafıza (kesin)
A17: Rotterdam Dresuar 120 (program REF) | B17: Ara bölme | C17: 356 | D17: 150 | E17: 18 | F17: 1 | G17: 18 mm MDF | H17: Program / hafıza (kesin)
A18: Rotterdam Dresuar 120 (program REF) | B18: Klapa (çekmece ön) | C18: 542.5 | D18: 166 | E18: 18 | F18: 2 | G18: 18 mm MDF | H18: Program / hafıza (kesin) | I18: 8 mm cepli, üstüne 8 mm Tweety tarama yapışır
A19: Rotterdam Dresuar 120 (program REF) | B19: Çekmece yan | C19: 350 | D19: 102 | E19: 18 | F19: 4 | G19: 18 mm MDF | H19: Program / hafıza (kesin) | I19: 9 mm kanal, alttan 9–18 mm, 8 derin
A20: Rotterdam Dresuar 120 (program REF) | B20: Çekmece ön/arka | C20: 475 | D20: 84 | E20: 18 | F20: 4 | G20: 18 mm MDF | H20: Program / hafıza (kesin)
A21: Rotterdam Dresuar 120 (program REF) | B21: Çekmece tabanı | C21: 490 | D21: 350 | E21: 8 | F21: 2 | G21: 8 mm MDF | H21: Program / hafıza (kesin) | I21: Ayrı malzeme
A22: Tivoli ayak (Cannelé) — 1 ayak | B22: Disk Ø90 | C22: 90 | D22: 90 | E22: 18 | F22: 3 | G22: 18 mm MDF | H22: Program / hafıza (kesin) | I22: Alt / orta / üst
A23: Tivoli ayak (Cannelé) — 1 ayak | B23: Şapka Ø150 | C23: 150 | D23: 150 | E23: 18 | F23: 1 | G23: 18 mm MDF | H23: Program / hafıza (kesin) | I23: Ø10 cıvata delikleri, havşa
A24: Tivoli ayak (Cannelé) — 1 ayak | B24: Tweety tarama panel | C24: 283 | D24: 714 | E24: 8 | F24: 1 | G24: 8 mm MDF | H24: Program / hafıza (kesin) | I24: Mevcut Tweety programıyla
A25: Tivoli ayak (Cannelé) — 1 ayak | B25: Çıta (elde) | D25: 714 | E25: 18 | G25: 18 mm MDF | H25: Claude tahmini | I25: Adet/ölçü elde — kaç adet? (Sorular)
A26: Como masa ayağı — 1 ayak | B26: Tarama panel | C26: 1233 | E26: 18 | F26: 1 | G26: 18 mm MDF | H26: Program / hafıza (kesin) | I26: Panel boyu 1233 sabit; yükseklik teyit (Sorular)
A27: Como masa ayağı — 1 ayak | B27: Kapak Ø390 (dolu disk) | C27: 390 | D27: 390 | E27: 18 | F27: 2 | G27: 18 mm MDF | H27: Program / hafıza (kesin) | I27: Alt + üst, ara halka yok
A28: Como masa ayağı — 1 ayak | B28: Çeyrek yay (şapka) | E28: 18 | F28: 4 | G28: 18 mm MDF | H28: Program / hafıza (kesin) | I28: Ø8 tam delik, fireden
A29: Como sehpa ayağı Ø39 — 1 ayak | B29: Tarama panel | C29: 1233 | E29: 18 | F29: 1 | G29: 18 mm MDF | H29: Program / hafıza (kesin) | I29: H 382 / 432 / 482 — panel yüksekliği teyit
A30: Como sehpa ayağı Ø39 — 1 ayak | B30: Kapak Ø390 | C30: 390 | D30: 390 | E30: 18 | F30: 2 | G30: 18 mm MDF | H30: Program / hafıza (kesin) | I30: 4×Ø8 tam delik, 310 baklava
A31: Bubble masa ayağı — 1 ayak | B31: Konik panel (açınım) | D31: 714 | E31: 18 | F31: 1 | G31: 18 mm MDF | H31: Program / hafıza (kesin) | I31: Ø548,7 / Ø305,4, eğim 9,67° — BUBBLE_P1_REV
A32: Bubble masa ayağı — 1 ayak | B32: Üst tabla Ø548,7 | C32: 548.7 | D32: 548.7 | E32: 18 | F32: 1 | G32: 18 mm MDF | H32: Program / hafıza (kesin) | I32: 4×Ø8 tam delik, 400 baklava
A33: Bubble masa ayağı — 1 ayak | B33: Dar uç kapak Ø305,4 | C33: 305.4 | D33: 305.4 | E33: 18 | F33: 1 | G33: 18 mm MDF | H33: Program / hafıza (kesin) | I33: V91 gönye
A34: Bubble masa (deneme seti) | B34: Tabla Ø1200 | C34: 1200 | D34: 1200 | E34: 18 | F34: 1 | G34: 18 mm MDF | H34: Program / hafıza (kesin) | I34: V91 14 mm inceltme
A35: Bubble büyük sehpa ayağı | B35: Konik panel (açınım) | D35: 382 | E35: 18 | F35: 1 | G35: 18 mm MDF | H35: Program / hafıza (kesin) | I35: Ø497,7 / Ø297,8, eğim 14,66°
A36: Bubble küçük sehpa ayağı | B36: Konik panel (açınım) | D36: 432 | E36: 18 | F36: 1 | G36: 18 mm MDF | H36: Program / hafıza (kesin) | I36: Ø348 / Ø198, eğim 9,85°
A37: Bubble sehpa (deneme seti) | B37: Tabla Ø900 + Ø700 | C37: 900 | D37: 900 | E37: 18 | F37: 1 | G37: 18 mm MDF | H37: Program / hafıza (kesin) | I37: Ø700 ayrıca 1 adet
A38: Datça Masa | B38: Tabla | C38: 2000 | D38: 1000 | E38: 18 | F38: 1 | G38: 18 mm meşe kaplama | H38: Claude tahmini | I38: Ölçü siparişe göre
A39: Datça Masa | B39: Kalınlaştırma halkası (2 kat) | C39: 65 | E39: 18 | F39: 2 | G39: 18 mm meşe kaplama | H39: Claude tahmini | I39: 65 mm genişlik, çevre boyunca parçalı; 18+18+18 = 54
A40: Bugatti Orta Sehpa | B40: Tabla | C40: 1300 | D40: 700 | E40: 18 | F40: 1 | G40: Traverten | H40: Program / hafıza (kesin) | I40: Kenar 3 kat → 54 mm
...

Sheet Sorular
A1: # | B1: Soru | C1: Cevabınız
A2: 1 | B2: Torino Yan Sehpa Tweety Ayak (Ø39 H43) ve "… H45" kütüphanede iki ayrı ürün. Tek ürün yapıp H'yi siparişte seçelim mi?
A3: 2 | B3: "Star TV Ünitesi Şömine 200cm" ölçüsü En128, "Star TV Ünitesi Şömineli" En200 + not "128cm dimplex şömineye göre". Biri şömine nişi mi, yoksa ikisi aynı ürün mü?
A4: 3 | B4: Tweety SEHPA ayağı tablaya nasıl bağlanıyor: Slim Bugatti sehpa kaydında dübel + M8 civata var, Como sehpada kapaktan vida geçiyor. Tweety sehpa için hangisi?
A5: 4 | B5: Tivoli/Cannelé ayakta elde kesilen çıta kaç adet ve ölçüsü ne? Cıvata M6 mı M8 mi?
A6: 5 | B6: Como ayak tarama panelinin yüksekliği = ayak H mı, yoksa H − 36 (kapaklar panelin üstünde) mı?
A7: 6 | B7: Angel TV 4 kapak ama kütüphanede 6 menteşe + 3 amortisör yazıyor. 3 kapak aşağı açılır + 1 sabit mi? Değilse 8 menteşe + 4 amortisör yapalım.
A8: 7 | B8: Dörtdivan paneli: LED kaç metre? (Tahmin: panel eni × 2 = 7,6 m)
A9: 8 | B9: Bonbon dresuar 150 cm kaç kapak? (4 varsaydım)
A10: 9 | B10: Babuşka metal ayak Ø/H ölçüsü?
A11: 10 | B11: Ambalaj miktarları (karton, strafor köşe, streç, bant) paket başı doğru mu?

Sheet Listeler
A1: Ürünler | B1: Hırdavat | C1: Birim
A2: Bonbon Dresuar | B2: Ambalaj karton | C2: adet
A3: Rotterdam Dresuar Yanlar Tweety Kapaklar Düz | B3: Amortisör | C3: çift
A4: Tweety Çekmece Rotterdam Dresuar | B4: Ayak bağlantı civatası M6 | C4: takım
A5: Dörtdivan Duvar Paneli (Kertikli, LED'li) | B5: Ayak bağlantı civatası M8 | C5: m
A6: Bergamo Masa | B6: Bas-aç (push) | C6: m²
A7: Danish Oval Masa | B7: Cam altı şeffaf tampon | C7: kg
A8: Datça Masa | B8: Duvar dübeli + vida 6x60 | C8: paket
A9: Organik Bugatti Masa Camı 4mm | B9: Kablo geçiş rozeti | C9: plaka
A10: Rotterdam Masa | B10: Kalkar kapak mekanizması | C10: rulo
A11: Rotterdam Masa Tablası | B11: Kavela (dübel)
A12: Round Bugatti Masa | B12: Keçe (ayak altı)
A13: Slim Bugatti Masa | B13: Koli bandı
A14: Slim Masa | B14: Kulp
A15: Babuşka Orta Sehpa | B15: LED bağlantı seti (kablo + konnektör)
A16: Bergamo Orta Sehpa | B16: LED trafo
A17: Bonbon Tweety TV Sehpası | B17: LED şerit
A18: Danish Oval Orta Sehpa | B18: Menteşe
A19: Lazy Top Sehpa | B19: Pul (geniş) M6
A20: Ollie Orta Sehpa | B20: Pul (geniş) M8
A21: Rotterdam Orta Sehpa | B21: Raf pimi
A22: Rotterdam Orta Sehpa Tablası | B22: Strafor köşe
... A30: Sineklik Cam 1 | B30: — (tedarikçi dahil)
A31: Sineklik Cam 2
A32: Sineklik Cam 3
A33: Sineklik Kapı Ev Çıkış (Soldan Sağa Açılacak)
A34: Sineklik İkinci Mutfak (Soldan Sağa Açılacak)
A35: Angel TV Ünitesi 4 Kapak, Lazer TV Metal Ayak
A36: Bonbon TV Ünitesi
A37: Dolap, Lazer TV Metal Ayak
A38: Star TV Ünitesi Şömine 200cm
A39: Star TV Ünitesi Şömineli
A40: AYAK · Como · Masa
A41: AYAK · Como · Sehpa
A42: AYAK · XL Como · Masa
... A61: KAPAK KURALI
